Workbook

Sheet Sheet1
B1: DKIST-16 | C1: DKIST-64 | D1: EST-16 | E1: EST-64 | F1: GeMS | G1: MAD | H1: MAVIS | I1: MORFEO | J1: NFIRAOS | K1: ALASCA | L1: ALASCA
A2: D | B2: 4 | C2: 4 | D2: 4.2 | E2: 4.2 | F2: 8 | G2: 8 | H2: 8.2 | I2: 38.5 | J2: 30 | K2: 1 | L2: 1
A3: wvl | B3: 5.5e-07 | C3: 5.5e-07 | D3: 5e-07 | E3: 5e-07 | F3: 5.89e-07 | G3: 5.5e-07 | H3: 5.89e-07 | I3: 5.89e-07 | J3: 5.89e-07 | K3: 5.89e-07 | L3: 5.89e-07
A4: h | B4: 11200 | C4: 11200 | D4: 20000 | E4: 20000 | F4: 9000 | G4: 8500 | H4: 13500 | I4: 17500 | J4: 11800 | K4: 10000 | L4: 10000 | M4: 11200 | N4: 11200 | O4: 20000 | P4: 20000 | Q4: 9000 | R4: 8500 | S4: 13500 | T4: 17500 | U4: 11800
A5: zeta | B5: 0 | C5: 0 | D5: 0 | E5: 0 | F5: 0 | G5: 0 | H5: 0 | I5: 0 | J5: 0 | K5: 0 | L5: 0
A6: r0 | B6: 0.09 | C6: 0.09 | D6: 0.07 | E6: 0.07 | F6: 0.14 | G6: 0.14 | H6: 0.14 | I6: 0.14 | J6: 0.19 | K6: 0.07 | L6: 0.07
A7: r0@wvl | B7: =B6*(B3/0.0000005)^(6/5) -> 0.10090524 | C7: =C6*(C3/0.0000005)^(6/5) -> 0.10090524 | D7: =D6*(D3/0.0000005)^(6/5) -> 0.07 | E7: =E6*(E3/0.0000005)^(6/5) -> 0.07 | F7: =F6*(F3/0.0000005)^(6/5) -> 0.17041287 | G7: =G6*(G3/0.0000005)^(6/5) -> 0.15696371 | H7: =H6*(H3/0.0000005)^(6/5) -> 0.17041287 | I7: =I6*(I3/0.0000005)^(6/5) -> 0.17041287 | ... L7: =L6*(L3/0.0000005)^(6/5) -> 0.085206434
A8: FoV | B8: 60 | C8: 60 | D8: 60 | E8: 60 | F8: 120 | G8: 120 | H8: 120 | I8: 160 | J8: 120 | K8: 5 | L8: 5
A9: cexpand | B9: 4 | C9: 4 | D9: 4 | E9: 4 | F9: 4 | G9: 4 | H9: 4 | I9: 4 | J9: 4 | K9: 4 | L9: 4
A10: wfs_pitch | B10: 0.093 | C10: 0.093 | D10: 0.08 | E10: 0.08 | F10: 0.5 | G10: 1 | H10: 0.216 | I10: 0.55 | J10: 0.5 | K10: =K2/K11 -> 0.1 | L10: =L2/L11 -> 0.1
A11: nxsub | B11: =B2/B10 -> 43.010753 | C11: =C2/C10 -> 43.010753 | D11: =D2/D10 -> 52.5 | E11: =E2/E10 -> 52.5 | F11: =F2/F10 -> 16 | G11: =G2/G10 -> 8 | H11: =H2/H10 -> 37.962963 | I11: =I2/I10 -> 70 | J11: =J2/J10 -> 60 | K11: 10 | L11: 10 | O11: =9*1452 -> 13068 | P11: =9*3847 -> 34623
A12: subpxl | B12: 16 | C12: 64 | D12: 16 | E12: 64 | F12: 16 | G12: 16 | H12: 16 | I12: 16 | J12: 16 | K12: 16 | L12: 64
A13: delta | B13: =B2/B12/B11 -> 0.0058125 | C13: =C2/C12/C11 -> 0.001453125 | D13: =D2/D12/D11 -> 0.005 | E13: =E2/E12/E11 -> 0.00125 | F13: =F2/F12/F11 -> 0.03125 | G13: =G2/G12/G11 -> 0.0625 | H13: =H2/H12/H11 -> 0.0135 | I13: =I2/I12/I11 -> 0.034375 | ... L13: =L2/L12/L11 -> 0.0015625
A14: nwfs | B14: 9 | C14: 9 | D14: 19 | E14: 19 | F14: 8 | G14: 11 | H14: 11 | I14: 9 | J14: 9 | K14: 1 | L14: 1
A15: n-isoplan | B15: =(B8)^2 -> 3600 | C15: =(C8)^2 -> 3600 | D15: =(D8)^2 -> 3600 | E15: =(E8)^2 -> 3600 | F15: 1 | G15: 1 | H15: 1 | I15: 1 | J15: 1 | K15: 1 | L15: 1
A16: ndm | B16: 3 | C16: 3 | D16: 5 | E16: 5 | F16: 3 | G16: 2 | H16: 3 | I16: 3 | J16: 2 | K16: 2 | L16: 2
A18: z | B18: =B4/COS(RADIANS(B5)) -> 11200 | C18: =C4/COS(RADIANS(C5)) -> 11200 | D18: =D4/COS(RADIANS(D5)) -> 20000 | E18: =E4/COS(RADIANS(E5)) -> 20000 | F18: =F4/COS(RADIANS(F5)) -> 9000 | G18: =G4/COS(RADIANS(G5)) -> 8500 | H18: =H4/COS(RADIANS(H5)) -> 13500 | I18: =I4/COS(RADIANS(I5)) -> 17500 | ... L18: =L4/COS(RADIANS(L5)) -> 10000
A19: D_ps | B19: =B2+B8*B18/206265+B9*B3/B7*B18 -> 7.5021344 | C19: =C2+C8*C18/206265+C9*C3/C7*C18 -> 7.5021344 | D19: =D2+D8*D18/206265+D9*D3/D7*D18 -> 10.589187 | E19: =E2+E8*E18/206265+E9*E3/E7*E18 -> 10.589187 | F19: =F2+F8*F18/206265+F9*F3/F7*F18 -> 13.36041 | G19: =G2+G8*G18/206265+G9*G3/G7*G18 -> 13.064231 | H19: =H2+H8*H18/206265+H9*H3/H7*H18 -> 16.240615 | I19: =I2+I8*I18/206265+I9*I3/I7*I18 -> 52.316712 | ... L19: =L2+L8*L18/206265+L9*L3/L7*L18 -> 1.5189116
A20: Dz | B20: =B2+B9*B3/B7*B18 -> 4.2441895 | C20: =C2+C9*C3/C7*C18 -> 4.2441895 | D20: =D2+D9*D3/D7*D18 -> 4.7714286 | E20: =E2+E9*E3/E7*E18 -> 4.7714286 | F20: =F2+F9*F3/F7*F18 -> 8.1244272 | G20: =G2+G9*G3/G7*G18 -> 8.1191358 | H20: =H2+H9*H3/H7*H18 -> 8.3866408 | I20: =I2+I9*I3/I7*I18 -> 38.741942 | ... L20: =L2+L9*L3/L7*L18 -> 1.2765049
A21: N_0 | B21: =B2/B13 -> 688.17204 | C21: =C2/C13 -> 2752.6882 | D21: =D2/D13 -> 840 | E21: =E2/E13 -> 3360 | F21: =F2/F13 -> 256 | G21: =G2/G13 -> 128 | H21: =H2/H13 -> 607.40741 | I21: =I2/I13 -> 1120 | ... L21: =L2/L13 -> 640
A22: N_z | B22: =B20/B13 -> 730.18314 | C22: =C20/C13 -> 2920.7326 | D22: =D20/D13 -> 954.28571 | E22: =E20/E13 -> 3817.1429 | F22: =F20/F13 -> 259.98167 | G22: =G20/G13 -> 129.90617 | H22: =H20/H13 -> 621.23265 | I22: =I20/I13 -> 1127.0383 | ... L22: =L20/L13 -> 816.96316
A24: N_ps | B24: =B19/B13 -> 1290.6898 | C24: =C19/C13 -> 5162.7591 | D24: =D19/D13 -> 2117.8375 | E24: =E19/E13 -> 8471.3498 | F24: =F19/F13 -> 427.53312 | G24: =G19/G13 -> 209.02769 | H24: =H19/H13 -> 1203.0085 | I24: =I19/I13 -> 1521.9407 | ... L24: =L19/L13 -> 972.10339
A25: N_prop | B25: =MAX(B2/2/B13+B20/2/B13+B3*B18/2/B13^2,B3*B18/B13^2) -> 800.34189 | C25: =MAX(C2/2/C13+C20/2/C13+C3*C18/2/C13^2,C3*C18/C13^2) -> 4295.3391 | D25: =MAX(D2/2/D13+D20/2/D13+D3*D18/2/D13^2,D3*D18/D13^2) -> 1097.1429 | E25: =MAX(E2/2/E13+E20/2/E13+E3*E18/2/E13^2,E3*E18/E13^2) -> 6788.5714 | F25: =MAX(F2/2/F13+F20/2/F13+F3*F18/2/F13^2,F3*F18/F13^2) -> 260.70495 | G25: =MAX(G2/2/G13+G20/2/G13+G3*G18/2/G13^2,G3*G18/G13^2) -> 129.55149 | H25: =MAX(H2/2/H13+H20/2/H13+H3*H18/2/H13^2,H3*H18/H13^2) -> 636.13485 | I25: =MAX(I2/2/I13+I20/2/I13+I3*I18/2/I13^2,I3*I18/I13^2) -> 1127.8807 | ... L25: =MAX(L2/2/L13+L20/2/L13+L3*L18/2/L13^2,L3*L18/L13^2) -> 2412.544
A26: N_wfssubap | B26: =B12 -> 16 | C26: =C12 -> 64 | D26: =D12 -> 16 | E26: =E12 -> 64 | F26: =F12 -> 16 | G26: =G12 -> 16 | H26: =H12 -> 16 | I26: =I12 -> 16 | ... L26: =L12 -> 64
A27: nxsub | B27: =B11 -> 43.010753 | C27: =C11 -> 43.010753 | D27: =D11 -> 52.5 | E27: =E11 -> 52.5 | F27: =F11 -> 16 | G27: =G11 -> 8 | H27: =H11 -> 37.962963 | I27: =I11 -> 70 | ... L27: =L11 -> 10
A28: total subap | B28: =B27^2/4*3.14 -> 1452.191 | C28: =C27^2/4*3.14 -> 1452.191 | D28: =D27^2/4*3.14 -> 2163.6562 | E28: =E27^2/4*3.14 -> 2163.6562 | F28: =F27^2/4*3.14 -> 200.96 | G28: =G27^2/4*3.14 -> 50.24 | H28: =H27^2/4*3.14 -> 1131.3314 | I28: =I27^2/4*3.14 -> 3846.5 | ... L28: =L27^2/4*3.14 -> 78.5
A30: t_ps | B30: 1.53 | C30: 20 | D30: 3.84 | E30: 50.2 | F30: 0.198 | G30: 0.0525 | H30: 1.34 | I30: 2.08 | J30: 1.3 | K30: 0.0694 | L30: 0.907
A31: t_prop | B31: 0.573 | C31: 25.2 | D31: 1.16 | E31: 70.6 | F31: 0.046 | G31: 0.00959 | H31: 0.342 | I31: 1.24 | J31: 0.874 | K31: 0.0449 | L31: 6.88
A32: t_FT | B32: 5.68e-05 | C32: 0.000184 | D32: 5.68e-05 | E32: 0.000184 | F32: 5.68e-05 | G32: 5.68e-05 | H32: 5.68e-05 | I32: 5.68e-05 | J32: 5.68e-05 | K32: 5.68e-05 | L32: 0.000184
A33: t_IG | B33: 3.64e-05 | C33: 7.87e-05 | D33: 3.64e-05 | E33: 7.87e-05 | F33: 3.64e-05 | G33: 3.64e-05 | H33: 3.64e-05 | I33: 3.64e-05 | J33: 3.64e-05 | K33: 3.64e-05 | L33: 7.87e-05
A34: t_G | B34: 2.85e-05 | C34: 5.84e-05 | D34: 2.85e-05 | E34: 5.84e-05 | F34: 2.85e-05 | G34: 2.85e-05 | H34: 2.85e-05 | I34: 2.85e-05 | J34: 2.85e-05 | K34: 2.85e-05 | L34: 5.84e-05
A36: T_ps | B36: =B30*B16 -> 4.59 | C36: =C30*C16 -> 60 | D36: =D30*D16 -> 19.2 | E36: =E30*E16 -> 251 | F36: =F30*F16 -> 0.594 | G36: =G30*G16 -> 0.105 | H36: =H30*H16 -> 4.02 | I36: =I30*I16 -> 6.24 | ... L36: =L30*L16 -> 1.814
A37: T_prop | B37: =B31*B14*(B16*2-1) -> 25.785 | C37: =C31*C14*(C16*2-1) -> 1134 | D37: =D31*D14*(D16*2-1) -> 198.36 | E37: =E31*E14*(E16*2-1) -> 12072.6 | F37: =F31*F14*(F16*2-1) -> 1.84 | G37: =G31*G14*(G16*2-1) -> 0.31647 | H37: =H31*H14*(H16*2-1) -> 18.81 | I37: =I31*I14*(I16*2-1) -> 55.8 | ... L37: =L31*L14*(L16*2-1) -> 20.64
A38: T_FT | B38: =B32*B28*B14*B15 -> 2672.4961 | C38: =C32*C28*C14*C15 -> 8657.3819 | D38: =D32*D28*D14*D15 -> 8406.0642 | E38: =E32*E28*E14*E15 -> 27230.912 | F38: =F32*F28*F14*F15 -> 0.091316224 | G38: =G32*G28*G14*G15 -> 0.031389952 | H38: =H32*H28*H14*H15 -> 0.70685589 | I38: =I32*I28*I14*I15 -> 1.9663308 | ... L38: =L32*L28*L14*L15 -> 0.014444
A39: T_IG | B39: =B33*B28*B14*B15 -> 1712.656 | C39: =C33*C28*C14*C15 -> 3702.9128 | D39: =D33*D28*D14*D15 -> 5386.9848 | E39: =E33*E28*E14*E15 -> 11647.135 | F39: =F33*F28*F14*F15 -> 0.058519552 | G39: =G33*G28*G14*G15 -> 0.020116096 | H39: =H33*H28*H14*H15 -> 0.45298511 | I39: =I33*I28*I14*I15 -> 1.2601134 | ... L39: =L33*L28*L14*L15 -> 0.00617795
A40: T_G | B40: =B14*B15*B28*B34 -> 1340.9532 | C40: =C14*C15*C28*C34 -> 2747.7777 | D40: =D14*D15*D28*D34 -> 4217.8315 | E40: =E14*E15*E28*E34 -> 8642.8547 | F40: =F14*F15*F28*F34 -> 0.04581888 | G40: =G14*G15*G28*G34 -> 0.01575024 | H40: =H14*H15*H28*H34 -> 0.35467241 | I40: =I14*I15*I28*I34 -> 0.98662725 | ... L40: =L14*L15*L28*L34 -> 0.0045844
A42: benefit-IG (%) | B42: =(B38-B39)/(B36+B37+B38)*100 -> 35.511873 | C42: =(C38-C39)/(C36+C37+C38)*100 -> 50.292123 | D42: =(D38-D39)/(D36+D37+D38)*100 -> 35.009404 | E42: =(E38-E39)/(E36+E37+E38)*100 -> 39.398229 | F42: =(F38-F39)/(F36+F37+F38)*100 -> 1.2987155 | G42: =(G38-G39)/(G36+G37+G38)*100 -> 2.4894796 | H42: =(H38-H39)/(H36+H37+H38)*100 -> 1.0786096 | I42: =(I38-I39)/(I36+I37+I38)*100 -> 1.1033555 | ... L42: =(L38-L39)/(L36+L37+L38)*100 -> 0.036789597
A43: benefit-IG (s) | B43: =B38-B39 -> 959.84017 | C43: =C38-C39 -> 4954.4691 | D43: =D38-D39 -> 3019.0794 | E43: =E38-E39 -> 15583.777 | F43: =F38-F39 -> 0.032796672 | G43: =G38-G39 -> 0.011273856 | H43: =H38-H39 -> 0.25387078 | I43: =I38-I39 -> 0.7062174 | ... L43: =L38-L39 -> 0.00826605
A44: benefit-G (s) | B44: =(B38-B40) -> 1331.543 | C44: =(C38-C40) -> 5909.6042 | D44: =(D38-D40) -> 4188.2327 | E44: =(E38-E40) -> 18588.057 | F44: =(F38-F40) -> 0.045497344 | G44: =(G38-G40) -> 0.015639712 | H44: =(H38-H40) -> 0.35218348 | I44: =(I38-I40) -> 0.97970355 | ... L44: =(L38-L40) -> 0.0098596
A45: benefit-G (%) | B45: =(B38-B40)/(B36+B37+B38)*100 -> 49.26402 | C45: =(C38-C40)/(C36+C37+C38)*100 -> 59.987565 | D45: =(D38-D40)/(D36+D37+D38)*100 -> 48.566967 | E45: =(E38-E40)/(E36+E37+E38)*100 -> 46.99352 | F45: =(F38-F40)/(F36+F37+F38)*100 -> 1.8016494 | G45: =(G38-G40)/(G36+G37+G38)*100 -> 3.4535427 | H45: =(H38-H40)/(H36+H37+H38)*100 -> 1.4963064 | I45: =(I38-I40)/(I36+I37+I38)*100 -> 1.5306354 | ... L45: =(L38-L40)/(L36+L37+L38)*100 -> 0.043881988
...

Sheet Sheet2
A1: =Sheet1!A74 -> 0 | B1: =Sheet1!B74 -> DKIST-16 | C1: =Sheet1!C74 -> DKIST-64 | D1: =Sheet1!D74 -> EST-16 | E1: =Sheet1!E74 -> EST-64 | F1: =Sheet1!G74 -> MAD | G1: =Sheet1!I74 -> MORFEO
A2: =Sheet1!A75 -> t_ps | B2: =Sheet1!B75 -> 1.53 | C2: =Sheet1!C75 -> 20 | D2: =Sheet1!D75 -> 3.84 | E2: =Sheet1!E75 -> 50.2 | F2: =Sheet1!G75 -> 0.0525 | G2: =Sheet1!I75 -> 2.08
A3: =Sheet1!A76 -> t_prop | B3: =Sheet1!B76 -> 0.573 | C3: =Sheet1!C76 -> 25.2 | D3: =Sheet1!D76 -> 1.16 | E3: =Sheet1!E76 -> 70.6 | F3: =Sheet1!G76 -> 0.00959 | G3: =Sheet1!I76 -> 1.24
A4: =Sheet1!A80 -> t_correlate | B4: =Sheet1!B80 -> 9e-05 | C4: =Sheet1!C80 -> 0.00038 | D4: =Sheet1!D80 -> 9e-05 | E4: =Sheet1!E80 -> 0.00038 | F4: =Sheet1!G80 -> 0 | G4: =Sheet1!I80 -> 0
A5: =Sheet1!A77 -> t_FT | B5: =Sheet1!B77 -> 5.68e-05 | C5: =Sheet1!C77 -> 0.000184 | D5: =Sheet1!D77 -> 5.68e-05 | E5: =Sheet1!E77 -> 0.000184 | F5: =Sheet1!G77 -> 5.68e-05 | G5: =Sheet1!I77 -> 5.68e-05
A6: =Sheet1!A78 -> t_IG | B6: =Sheet1!B78 -> 3.64e-05 | C6: =Sheet1!C78 -> 7.87e-05 | D6: =Sheet1!D78 -> 3.64e-05 | E6: =Sheet1!E78 -> 7.87e-05 | F6: =Sheet1!G78 -> 3.64e-05 | G6: =Sheet1!I78 -> 3.64e-05
A7: =Sheet1!A79 -> t_G | B7: =Sheet1!B79 -> 2.85e-05 | C7: =Sheet1!C79 -> 5.84e-05 | D7: =Sheet1!D79 -> 2.85e-05 | E7: =Sheet1!E79 -> 5.84e-05 | F7: =Sheet1!G79 -> 2.85e-05 | G7: =Sheet1!I79 -> 2.85e-05
A8: =Sheet1!A81 -> number ps | B8: =Sheet1!B16 -> 3 | C8: =Sheet1!C16 -> 3 | D8: =Sheet1!D16 -> 5 | E8: =Sheet1!E16 -> 5 | F8: =Sheet1!F16 -> 3 | G8: =Sheet1!G16 -> 2
A9: num_wfs_image | B9: =INT(Sheet1!B48*Sheet1!B50) -> 13069 | C9: =INT(Sheet1!C48*Sheet1!C50) -> 13069 | D9: =INT(Sheet1!D48*Sheet1!D50) -> 41109 | E9: =INT(Sheet1!E48*Sheet1!E50) -> 41109 | F9: =INT(Sheet1!F48*Sheet1!F50) -> 1607 | G9: =INT(Sheet1!G48*Sheet1!G50) -> 552
A10: num_iso | B10: =Sheet1!B52 -> 3600 | C10: =Sheet1!C52 -> 3600 | D10: =Sheet1!D52 -> 3600 | E10: =Sheet1!E52 -> 3600 | F10: =Sheet1!F52 -> 1 | G10: =Sheet1!G52 -> 1
A11: num_prop | B11: =(B8*2-1)*B9 -> 65345 | C11: =(C8*2-1)*C9 -> 65345 | D11: =(D8*2-1)*D9 -> 369981 | E11: =(E8*2-1)*E9 -> 369981 | F11: =(F8*2-1)*F9 -> 8035 | G11: =(G8*2-1)*G9 -> 1656
A12: =Sheet1!A84 -> T_ps | B12: =B8*B2 -> 4.59 | C12: =C8*C2 -> 60 | D12: =D8*D2 -> 19.2 | E12: =E8*E2 -> 251 | F12: =F8*F2 -> 0.1575 | G12: =G8*G2 -> 4.16
A13: =Sheet1!A85 -> T_prop | B13: =B11*B3 -> 37442.685 | C13: =C11*C3 -> 1646694 | D13: =D11*D3 -> 429177.96 | E13: =E11*E3 -> 26120659 | F13: =F11*F3 -> 77.05565 | G13: =G11*G3 -> 2053.44
A14: =Sheet1!A89 -> T_correlate | B14: =B4*B9 -> 1.17621 | C14: =C4*C9 -> 4.96622 | D14: =D4*D9 -> 3.69981 | E14: =E4*E9 -> 15.62142 | F14: =F4*F9 -> 0 | G14: =G4*G9 -> 0
A15: =Sheet1!A86 -> T_FT | B15: =B5*B9 -> 0.7423192 | C15: =C5*C9 -> 2.404696 | D15: =D5*D9 -> 2.3349912 | E15: =E5*E9 -> 7.564056 | F15: =F5*F9 -> 0.0912776 | G15: =G5*G9 -> 0.0313536
A16: =Sheet1!A87 -> T_IG | B16: =B6*B9 -> 0.4757116 | C16: =C6*C9 -> 1.0285303 | D16: =D6*D9 -> 1.4963676 | E16: =E6*E9 -> 3.2352783 | F16: =F6*F9 -> 0.0584948 | G16: =G6*G9 -> 0.0200928
A17: =Sheet1!A88 -> T_G | B17: =B7*B9 -> 0.3724665 | C17: =C7*C9 -> 0.7632296 | D17: =D7*D9 -> 1.1716065 | E17: =E7*E9 -> 2.4007656 | F17: =F7*F9 -> 0.0457995 | G17: =G7*G9 -> 0.015732
A18: Total_FT | B18: =B12+B13+B14+B15 -> 37449.194 | C18: =C12+C13+C14+C15 -> 1646761.4 | D18: =D12+D13+D14+D15 -> 429203.19 | E18: =E12+E13+E14+E15 -> 26120933 | F18: =F12+F13+F14+F15 -> 77.304428 | G18: =G12+G13+G14+G15 -> 2057.6314
A19: =Sheet1!A90 -> benefit-IG (s) | B19: =B15-B16 -> 0.2666076 | C19: =C15-C16 -> 1.3761657 | D19: =D15-D16 -> 0.8386236 | E19: =E15-E16 -> 4.3287777 | F19: =F15-F16 -> 0.0327828 | G19: =G15-G16 -> 0.0112608
A20: =Sheet1!A91 -> benefit-G (s) | B20: =B15-B17 -> 0.3698527 | C20: =C15-C17 -> 1.6414664 | D20: =D15-D17 -> 1.1633847 | E20: =E15-E17 -> 5.1632904 | F20: =F15-F17 -> 0.0454781 | G20: =G15-G17 -> 0.0156216
A21: benefit-IG (%) | B21: =B19/B18*100 -> 0.00071191813 | C21: =C19/C18*100 -> 8.356801e-05 | D21: =D19/D18*100 -> 0.00019539081 | E21: =E19/E18*100 -> 1.6572064e-05 | F21: =F19/F18*100 -> 0.042407403 | G21: =G19/G18*100 -> 0.00054727004
A22: benefit-G (%) | B22: =B20/B18 -> 9.8761192e-06 | C22: =C20/C18 -> 9.9678462e-07 | D22: =D20/D18 -> 2.7105686e-06 | E22: =E20/E18 -> 1.9766868e-07 | F22: =F20/F18 -> 0.00058829877 | G22: =G20/G18 -> 7.5920305e-06

Sheet Sheet3
A1: =Sheet1!A74 -> 0 | B1: =Sheet1!B74 -> DKIST-16 | C1: =Sheet1!C74 -> DKIST-64 | D1: =Sheet1!D74 -> EST-16 | E1: =Sheet1!E74 -> EST-64 | F1: =Sheet1!G74 -> MAD | G1: =Sheet1!I74 -> MORFEO
A2: =Sheet1!A75 -> t_ps | B2: =Sheet1!B75 -> 1.53 | C2: =Sheet1!C75 -> 20 | D2: =Sheet1!D75 -> 3.84 | E2: =Sheet1!E75 -> 50.2 | F2: =Sheet1!G75 -> 0.0525 | G2: =Sheet1!I75 -> 2.08
A3: =Sheet1!A76 -> t_prop | B3: =Sheet1!B76 -> 0.573 | C3: =Sheet1!C76 -> 25.2 | D3: =Sheet1!D76 -> 1.16 | E3: =Sheet1!E76 -> 70.6 | F3: =Sheet1!G76 -> 0.00959 | G3: =Sheet1!I76 -> 1.24
A4: =Sheet1!A80 -> t_correlate | B4: =Sheet1!B80 -> 9e-05 | C4: =Sheet1!C80 -> 0.00038 | D4: =Sheet1!D80 -> 9e-05 | E4: =Sheet1!E80 -> 0.00038 | F4: =Sheet1!G80 -> 0 | G4: =Sheet1!I80 -> 0
A5: =Sheet1!A77 -> t_FT | B5: =Sheet1!B77 -> 5.68e-05 | C5: =Sheet1!C77 -> 0.000184 | D5: =Sheet1!D77 -> 5.68e-05 | E5: =Sheet1!E77 -> 0.000184 | F5: =Sheet1!G77 -> 5.68e-05 | G5: =Sheet1!I77 -> 5.68e-05
A6: =Sheet1!A78 -> t_IG | B6: =Sheet1!B78 -> 3.64e-05 | C6: =Sheet1!C78 -> 7.87e-05 | D6: =Sheet1!D78 -> 3.64e-05 | E6: =Sheet1!E78 -> 7.87e-05 | F6: =Sheet1!G78 -> 3.64e-05 | G6: =Sheet1!I78 -> 3.64e-05
A7: =Sheet1!A79 -> t_G | B7: =Sheet1!B79 -> 2.85e-05 | C7: =Sheet1!C79 -> 5.84e-05 | D7: =Sheet1!D79 -> 2.85e-05 | E7: =Sheet1!E79 -> 5.84e-05 | F7: =Sheet1!G79 -> 2.85e-05 | G7: =Sheet1!I79 -> 2.85e-05
A8: =Sheet1!A81 -> number ps | B8: =Sheet1!B16 -> 3 | C8: =Sheet1!C16 -> 3 | D8: =Sheet1!D16 -> 5 | E8: =Sheet1!E16 -> 5 | F8: =Sheet1!F16 -> 3 | G8: =Sheet1!G16 -> 2
A9: num_wfs_image | B9: =INT(Sheet1!B48*Sheet1!B50) -> 13069 | C9: =INT(Sheet1!C48*Sheet1!C50) -> 13069 | D9: =INT(Sheet1!D48*Sheet1!D50) -> 41109 | E9: =INT(Sheet1!E48*Sheet1!E50) -> 41109 | F9: =INT(Sheet1!F48*Sheet1!F50) -> 1607 | G9: =INT(Sheet1!G48*Sheet1!G50) -> 552
A10: num_iso | B10: =Sheet1!B52 -> 3600 | C10: =Sheet1!C52 -> 3600 | D10: =Sheet1!D52 -> 3600 | E10: =Sheet1!E52 -> 3600 | F10: =Sheet1!F52 -> 1 | G10: =Sheet1!G52 -> 1
A11: num_prop | B11: =(B8*2-1)*B9 -> 65345 | C11: =(C8*2-1)*C9 -> 65345 | D11: =(D8*2-1)*D9 -> 369981 | E11: =(E8*2-1)*E9 -> 369981 | F11: =(F8*2-1)*F9 -> 8035 | G11: =(G8*2-1)*G9 -> 1656
A12: =Sheet1!A84 -> T_ps | B12: =B8*B2 -> 4.59 | C12: =C8*C2 -> 60 | D12: =D8*D2 -> 19.2 | E12: =E8*E2 -> 251 | F12: =F8*F2 -> 0.1575 | G12: =G8*G2 -> 4.16
A13: =Sheet1!A85 -> T_prop | B13: =B11*B3 -> 37442.685 | C13: =C11*C3 -> 1646694 | D13: =D11*D3 -> 429177.96 | E13: =E11*E3 -> 26120659 | F13: =F11*F3 -> 77.05565 | G13: =G11*G3 -> 2053.44
A14: =Sheet1!A89 -> T_correlate | B14: =B4*B9 -> 1.17621 | C14: =C4*C9 -> 4.96622 | D14: =D4*D9 -> 3.69981 | E14: =E4*E9 -> 15.62142 | F14: =F4*F9 -> 0 | G14: =G4*G9 -> 0
A15: =Sheet1!A86 -> T_FT | B15: =B5*B9 -> 0.7423192 | C15: =C5*C9 -> 2.404696 | D15: =D5*D9 -> 2.3349912 | E15: =E5*E9 -> 7.564056 | F15: =F5*F9 -> 0.0912776 | G15: =G5*G9 -> 0.0313536
A16: =Sheet1!A87 -> T_IG | B16: =B6*B9 -> 0.4757116 | C16: =C6*C9 -> 1.0285303 | D16: =D6*D9 -> 1.4963676 | E16: =E6*E9 -> 3.2352783 | F16: =F6*F9 -> 0.0584948 | G16: =G6*G9 -> 0.0200928
A17: =Sheet1!A88 -> T_G | B17: =B7*B9 -> 0.3724665 | C17: =C7*C9 -> 0.7632296 | D17: =D7*D9 -> 1.1716065 | E17: =E7*E9 -> 2.4007656 | F17: =F7*F9 -> 0.0457995 | G17: =G7*G9 -> 0.015732
A18: Total_FT | B18: =B12+B13+B14+B15 -> 37449.194 | C18: =C12+C13+C14+C15 -> 1646761.4 | D18: =D12+D13+D14+D15 -> 429203.19 | E18: =E12+E13+E14+E15 -> 26120933 | F18: =F12+F13+F14+F15 -> 77.304428 | G18: =G12+G13+G14+G15 -> 2057.6314
A19: =Sheet1!A90 -> benefit-IG (s) | B19: =B15-B16 -> 0.2666076 | C19: =C15-C16 -> 1.3761657 | D19: =D15-D16 -> 0.8386236 | E19: =E15-E16 -> 4.3287777 | F19: =F15-F16 -> 0.0327828 | G19: =G15-G16 -> 0.0112608
A20: =Sheet1!A91 -> benefit-G (s) | B20: =B15-B17 -> 0.3698527 | C20: =C15-C17 -> 1.6414664 | D20: =D15-D17 -> 1.1633847 | E20: =E15-E17 -> 5.1632904 | F20: =F15-F17 -> 0.0454781 | G20: =G15-G17 -> 0.0156216
A21: benefit-IG (%) | B21: =B19/B18*100 -> 0.00071191813 | C21: =C19/C18*100 -> 8.356801e-05 | D21: =D19/D18*100 -> 0.00019539081 | E21: =E19/E18*100 -> 1.6572064e-05 | F21: =F19/F18*100 -> 0.042407403 | G21: =G19/G18*100 -> 0.00054727004
A22: benefit-G (%) | B22: =B20/B18*100 -> 0.00098761192 | C22: =C20/C18*100 -> 9.9678462e-05 | D22: =D20/D18*100 -> 0.00027105686 | E22: =E20/E18*100 -> 1.9766868e-05 | F22: =F20/F18*100 -> 0.058829877 | G22: =G20/G18*100 -> 0.00075920305
